"from selenium import webdriver

desired_caps = {
    'platformName': 'Android',
    'deviceName': 'Android Emulator',
    'app': 'path/to/your/app.apk'
}

driver = webdriver.Remote('http://localhost:4723/wd/hub', desired_caps)",4
write a python script for me to load chrome and search dota2 on Android simulator using appuim,"from appium import webdriver

desired_caps = {
    'platformName': 'Android',
    'deviceName': 'Android Emulator',
    'browserName': 'Chrome'
}

driver = webdriver.Remote('http://localhost:4723/wd/hub', desired_caps)

driver.get('https://www.google.com')

search_box = driver.find_element_by_name('q')
search_box.send_keys('dota2')
search_box.submit()"
"There is an error in your code, error message is Traceback (most recent call last):
  File ""generated_code.py"", line 9, in <module>
    driver = webdriver.Remote('http://localhost:4723/wd/hub', desired_caps)
  File ""/Users/cm/opt/anaconda3/envs/chatGPT/lib/python3.8/site-packages/appium/webdriver/webdriver.py"", line 234, in __init__
    super().__init__(
  File ""/Users/cm/opt/anaconda3/envs/chatGPT/lib/python3.8/site-packages/selenium/webdriver/remote/webdriver.py"", line 288, in __init__
    self.start_session(capabilities, browser_profile)
  File ""/Users/cm/opt/anaconda3/envs/chatGPT/lib/python3.8/site-packages/appium/webdriver/webdriver.py"", line 324, in start_session
    response = self.execute(RemoteCommand.NEW_SESSION, w3c_caps)
  File ""/Users/cm/opt/anaconda3/envs/chatGPT/lib/python3.8/site-packages/selenium/webdriver/remote/webdriver.py"", line 444, in execute
    self.error_handler.check_response(response)
  File ""/Users/cm/opt/anaconda3/envs/chatGPT/lib/python3.8/site-packages/selenium/webdriver/remote/errorhandler.py"", line 249, in check_response
    raise exception_class(message, screen, stacktrace)
selenium.common.exceptions.WebDriverException: Message: An unknown server-side error occurred while processing the command. Original error: No Chromedriver found that can automate Chrome '83.0.4103'. You could also try to enable automated chromedrivers download server feature. See https://github.com/appium/appium/blob/master/docs/en/writing-running-appium/web/chromedriver.md for more details
Stacktrace:
UnknownError: An unknown server-side error occurred while processing the command. Original error: No Chromedriver found that can automate Chrome '83.0.4103'. You could also try to enable automated chromedrivers download server feature. See https://github.com/appium/appium/blob/master/docs/en/writing-running-appium/web/chromedriver.md for more details
    at getResponseForW3CError (/Applications/Appium.app/Contents/Resources/app/node_modules/appium/node_modules/appium-base-driver/lib/protocol/errors.js:804:9)
    at asyncHandler (/Applications/Appium.app/Contents/Resources/app/node_modules/appium/node_modules/appium-base-driver/lib/protocol/protocol.js:392:37)
. return the whole new code","from appium import webdriver

desired_caps = {
    'platformName': 'Android',
    'deviceName': 'Android Emulator',
    'automationName': 'UiAutomator2',
    'app': 'path/to/your/app.apk'
}

driver = webdriver.Remote('http://localhost:4723/wd/hub', desired_caps)"
"There is an error in your code, error message is Traceback (most recent call last):
  File ""generated_code.py"", line 10, in <module>
    driver = webdriver.Remote('http://localhost:4723/wd/hub', desired_caps)
  File ""/Users/cm/opt/anaconda3/envs/chatGPT/lib/python3.8/site-packages/appium/webdriver/webdriver.py"", line 234, in __init__
    super().__init__(
  File ""/Users/cm/opt/anaconda3/envs/chatGPT/lib/python3.8/site-packages/selenium/webdriver/remote/webdriver.py"", line 288, in __init__
    self.start_session(capabilities, browser_profile)
  File ""/Users/cm/opt/anaconda3/envs/chatGPT/lib/python3.8/site-packages/appium/webdriver/webdriver.py"", line 324, in start_session
    response = self.execute(RemoteCommand.NEW_SESSION, w3c_caps)
  File ""/Users/cm/opt/anaconda3/envs/chatGPT/lib/python3.8/site-packages/selenium/webdriver/remote/webdriver.py"", line 444, in execute
    self.error_handler.check_response(response)
  File ""/Users/cm/opt/anaconda3/envs/chatGPT/lib/python3.8/site-packages/selenium/webdriver/remote/errorhandler.py"", line 249, in check_response
    raise exception_class(message, screen, stacktrace)
selenium.common.exceptions.WebDriverException: Message: An unknown server-side error occurred while processing the command. Original error: The application at 'path/to/your/app.apk' does not exist or is not accessible
Stacktrace:
UnknownError: An unknown server-side error occurred while processing the command. Original error: The application at 'path/to/your/app.apk' does not exist or is not accessible
    at getResponseForW3CError (/Applications/Appium.app/Contents/Resources/app/node_modules/appium/node_modules/appium-base-driver/lib/protocol/errors.js:804:9)
    at asyncHandler (/Applications/Appium.app/Contents/Resources/app/node_modules/appium/node_modules/appium-base-driver/lib/protocol/protocol.js:392:37)
. return the whole new code","desired_caps = {
    ""platformName"": ""Android"",
    ""deviceName"": ""Android Emulator"",
    ""app"": ""path/to/your/app.apk""
}

driver = webdriver.Remote('http://localhost:4723/wd/hub', desired_caps)"
"There is an error in your code, error message is Traceback (most recent call last):
  File ""generated_code.py"", line 7, in <module>
    driver = webdriver.Remote('http://localhost:4723/wd/hub', desired_caps)
NameError: name 'webdriver' is not defined
. return the whole new code","from selenium import webdriver

desired_caps = {
    'platformName': 'Android',
    'deviceName': 'Android Emulator',
    'app': 'path/to/your/app.apk'
}

driver = webdriver.Remote('http://localhost:4723/wd/hub', desired_caps)"
